Workbook

Sheet Start_Here
A1: Project HEATWISE — Urban Heat Islands and Heat Domes: a monitoring-and-control simulation
A2: SPCE0019 Project Simulation | Interactive what-if workbook | Open data: ECA&D daily observations, London Heathrow, May–September 1979–2023
B4: Scenario | C4: It is spring 2026. A London heat resilience programme (fictional: Project HEATWISE) has completed risk identification, assessment and mitigation planning. Your group is the programme's Risk & Assurance team, responsible for step 4: MONITORING AND CONTROL. Replay real summers — above all the July 2022 heat dome — as if they were live, decide when to act, and turn what monitoring reveals into new or changed requirements.
B5: Core idea | C5: Monitoring and control is not the end of the risk process — it is a feedback loop. Live key risk indicators detect new and changing risks; each detection is the first step of requirements engineering (elicit → analyse → specify → validate). New requirements are then modelled, simulated and optimised (thresholds, tipping points, algorithm drift) and fed back into identification.
B6: The loop | C6: 1 IDENTIFY → 2 ASSESS → 3 MITIGATE → 4 MONITOR & CONTROL → (trigger) → REQUIREMENTS ENGINEERING → MODEL · SIMULATE · OPTIMISE → back to 1 IDENTIFY
B7: Four lenses | C7: DATA: quality flags, sensor drift, single-station bias. AI: a forecasting model that drifts as the climate shifts. SUSTAINABILITY: cooling that adds carbon (maladaptation) vs nature-based solutions. DIVERSITY & INCLUSION: who is exposed, and who the monitoring misses.
B8: How to use | C8: 1) Explore what-if scenarios in the HEATWISE dashboard: https://sbegucl.github.io/heatwise/ 2) Press Record scenario and paste each row into Scenario_Log. 3) Shortlist, score and vote in Decision_Matrix, and record your decision. 4) Complete Risk_Register and Req_Feedback. The other sheets hold the same model as the dashboard for checking figures, tracing formulas and running Solver on Optimise.
B9: Colour key | C9: Blue bold text on yellow = input you may change. Black = formula. Green = link from another sheet. Red/amber/green fills = status. Don't overwrite black cells — copy the workbook first if you want to experiment structurally.
B10: Spot the incident | C10: Look at 19 July 2022 on Monitor_Control with QA policy 'Use raw'. The recorded maximum is lower than the daily mean — physically impossible — and the source flags it as suspect. What would your monitoring system have done on the most dangerous day of the summer?
B11: Honesty about the model | C11: This is a teaching model. The UHI uplifts, group profiles, capacity and intervention effects are assumptions for groups to evidence or challenge. The alert logic is simplified: UKHSA's real heat-health alerts are impact-based. Heathrow is an airport station, not the city centre — that limitation is part of the exercise.
B12: Recalculation | C12: Excel recalculates automatically. If values look stale, press F9. The workbook uses only standard functions (no macros), so it also works in LibreOffice and most online spreadsheet tools that open .xlsx.
B14: Sheet map
B15: Scenario_Log | C15: Paste target for every scenario recorded from the dashboard, scored against the six board targets.
B16: Decision_Matrix | C16: Group weights, shortlist, scores, vote, final decision, relaxed target and dissent log.
B17: Control_Panel | C17: All what-if levers and the live KRI dashboard.
B18: Monitor_Control | C18: The daily feedback loop for the chosen year and neighbourhood: observe, QA, compare, detect, act.
B19: AI_Model | C19: Transparent OLS forecaster; training window; leakage check.
B20: Tipping_Points | C20: Threshold and climate-shift sweeps; stock-and-flow tipping model.
B21: Equity_Lens | C21: Neighbourhood typologies, representation gap, group exposure ranking.
B22: Sustainability | C22: Cooling degree-days, AC electricity, carbon and AI compute.
B23: Optimise | C23: Intervention portfolio, budget, deaths averted, carbon trade-off.
B24: Risk_Register | C24: Module template extended with KRIs, triggers and requirement links.
B25: Req_Feedback | C25: Change requests generated by triggers; disagreement log.
B26: Annual_Trend | C26: 1979–2023 moving baseline and model drift by year.
... B29: Sources_Licence | C29: Data provenance, licences and evidence for defaults.

Sheet Scenario_Log
A1: Scenario_Log — every what-if scenario your group tests
A2: Run scenarios in the HEATWISE dashboard (https://sbegucl.github.io/heatwise/). Press Record scenario, copy the row, then click the first empty cell in column B here and paste. Rows 5–6 are examples: keep them for comparison or delete them.
B3: SCENARIO | E3: SETTINGS | L3: INTERVENTION LEVELS (0–1) | S3: DEATHS (London-wide) | V3: COOLING CARBON | Y3: REPRESENTATION GAP (Inner London) | AB3: AI HOT-DAY RECALL % | AE3: TIPPING DAYS (Inner London) | AH3: TARGETS MET
A4: ID | B4: Recorded by | C4: Scenario name | D4: Year | E4: Mitigation | F4: Hot-day °C | G4: Warm-night °C | H4: Capacity °C·d | I4: QA policy | J4: Sensor drift °C/30d | K4: AI trained to | L4: Greening | M4: Cool roofs | N4: Cooling centres | O4: Sensors | P4: MLOps retrain | Q4: AC subsidy | R4: Cost £m | S4: Deaths +0°C | T4: Deaths +1°C | U4: Deaths +2°C | V4: Carbon tCO₂e +0°C | W4: Carbon tCO₂e +1°C | X4: Carbon tCO₂e +2°C | Y4: Rep. gap days +0°C | Z4: Rep. gap days +1°C | AA4: Rep. gap days +2°C | AB4: AI recall % +0°C | AC4: AI recall % +1°C | AD4: AI recall % +2°C | AE4: Tipping days +0°C | AF4: Tipping days +1°C | AG4: Tipping days +2°C | AH4: Targets met +0°C | AI4: Targets met +1°C | AJ4: Targets met +2°C
A5: =IF(B5="","","S"&TEXT(ROW()-4,"00")) -> S01 | B5: Example | C5: Baseline: no portfolio | D5: 2022 | E5: Baseline | F5: 28 | G5: 18 | H5: 40 | I5: Use raw | J5: 0 | K5: 1998 | L5: 0 | M5: 0 | N5: 0 | O5: 0 | P5: 0 | Q5: 0 | R5: 0 | S5: 387 | T5: 528 | U5: 695 | V5: 4160 | W5: 6016 | X5: 8466 | Y5: 19 | Z5: 15 | AA5: 22 | AB5: 37 | AC5: 36 | AD5: 46 | AE5: 3 | AF5: 6 | AG5: 10 | AH5: =IF(B5="","",(R5<=Budget)+(S5<Deaths_Appetite)+(V5<=Carbon_Budget)+(Y5=0)+(AB5>=Recall_Target*100)+(AE5=0)) -> 2 | AI5: =IF(B5="","",(R5<=Budget)+(T5<Deaths_Appetite)+(W5<=Carbon_Budget)+(Z5=0)+(AC5>=Recall_Target*100)+(AF5=0)) -> 2 | AJ5: =IF(B5="","",(R5<=Budget)+(U5<Deaths_Appetite)+(X5<=Carbon_Budget)+(AA5=0)+(AD5>=Recall_Target*100)+(AG5=0)) -> 2
A6: =IF(B6="","","S"&TEXT(ROW()-4,"00")) -> S02 | B6: Example | C6: Default portfolio: five measures at 50%, no AC | D6: 2022 | E6: With interventions | F6: 28 | G6: 18 | H6: 40 | I6: Use raw | J6: 0 | K6: 1998 | L6: 0.5 | M6: 0.5 | N6: 0.5 | O6: 0.5 | P6: 0.5 | Q6: 0 | R6: 35.3 | S6: 292 | T6: 404 | U6: 541 | V6: 2413 | W6: 4082 | X6: 6294 | Y6: 15 | Z6: 6 | AA6: 15 | AB6: 65 | AC6: 66 | AD6: 66 | AE6: 1 | AF6: 5 | AG6: 8 | AH6: =IF(B6="","",(R6<=Budget)+(S6<Deaths_Appetite)+(V6<=Carbon_Budget)+(Y6=0)+(AB6>=Recall_Target*100)+(AE6=0)) -> 2 | AI6: =IF(B6="","",(R6<=Budget)+(T6<Deaths_Appetite)+(W6<=Carbon_Budget)+(Z6=0)+(AC6>=Recall_Target*100)+(AF6=0)) -> 2 | AJ6: =IF(B6="","",(R6<=Budget)+(U6<Deaths_Appetite)+(X6<=Carbon_Budget)+(AA6=0)+(AD6>=Recall_Target*100)+(AG6=0)) -> 2
A7: =IF(B7="","","S"&TEXT(ROW()-4,"00")) | AH7: =IF(B7="","",(R7<=Budget)+(S7<Deaths_Appetite)+(V7<=Carbon_Budget)+(Y7=0)+(AB7>=Recall_Target*100)+(AE7=0)) | AI7: =IF(B7="","",(R7<=Budget)+(T7<Deaths_Appetite)+(W7<=Carbon_Budget)+(Z7=0)+(AC7>=Recall_Target*100)+(AF7=0)) | AJ7: =IF(B7="","",(R7<=Budget)+(U7<Deaths_Appetite)+(X7<=Carbon_Budget)+(AA7=0)+(AD7>=Recall_Target*100)+(AG7=0))
A8: =IF(B8="","","S"&TEXT(ROW()-4,"00")) | AH8: =IF(B8="","",(R8<=Budget)+(S8<Deaths_Appetite)+(V8<=Carbon_Budget)+(Y8=0)+(AB8>=Recall_Target*100)+(AE8=0)) | AI8: =IF(B8="","",(R8<=Budget)+(T8<Deaths_Appetite)+(W8<=Carbon_Budget)+(Z8=0)+(AC8>=Recall_Target*100)+(AF8=0)) | AJ8: =IF(B8="","",(R8<=Budget)+(U8<Deaths_Appetite)+(X8<=Carbon_Budget)+(AA8=0)+(AD8>=Recall_Target*100)+(AG8=0))
A9: =IF(B9="","","S"&TEXT(ROW()-4,"00")) | AH9: =IF(B9="","",(R9<=Budget)+(S9<Deaths_Appetite)+(V9<=Carbon_Budget)+(Y9=0)+(AB9>=Recall_Target*100)+(AE9=0)) | AI9: =IF(B9="","",(R9<=Budget)+(T9<Deaths_Appetite)+(W9<=Carbon_Budget)+(Z9=0)+(AC9>=Recall_Target*100)+(AF9=0)) | AJ9: =IF(B9="","",(R9<=Budget)+(U9<Deaths_Appetite)+(X9<=Carbon_Budget)+(AA9=0)+(AD9>=Recall_Target*100)+(AG9=0))
A10: =IF(B10="","","S"&TEXT(ROW()-4,"00")) | AH10: =IF(B10="","",(R10<=Budget)+(S10<Deaths_Appetite)+(V10<=Carbon_Budget)+(Y10=0)+(AB10>=Recall_Target*100)+(AE10=0)) | AI10: =IF(B10="","",(R10<=Budget)+(T10<Deaths_Appetite)+(W10<=Carbon_Budget)+(Z10=0)+(AC10>=Recall_Target*100)+(AF10=0)) | AJ10: =IF(B10="","",(R10<=Budget)+(U10<Deaths_Appetite)+(X10<=Carbon_Budget)+(AA10=0)+(AD10>=Recall_Target*100)+(AG10=0))
A11: =IF(B11="","","S"&TEXT(ROW()-4,"00")) | AH11: =IF(B11="","",(R11<=Budget)+(S11<Deaths_Appetite)+(V11<=Carbon_Budget)+(Y11=0)+(AB11>=Recall_Target*100)+(AE11=0)) | AI11: =IF(B11="","",(R11<=Budget)+(T11<Deaths_Appetite)+(W11<=Carbon_Budget)+(Z11=0)+(AC11>=Recall_Target*100)+(AF11=0)) | AJ11: =IF(B11="","",(R11<=Budget)+(U11<Deaths_Appetite)+(X11<=Carbon_Budget)+(AA11=0)+(AD11>=Recall_Target*100)+(AG11=0))
A12: =IF(B12="","","S"&TEXT(ROW()-4,"00")) | AH12: =IF(B12="","",(R12<=Budget)+(S12<Deaths_Appetite)+(V12<=Carbon_Budget)+(Y12=0)+(AB12>=Recall_Target*100)+(AE12=0)) | AI12: =IF(B12="","",(R12<=Budget)+(T12<Deaths_Appetite)+(W12<=Carbon_Budget)+(Z12=0)+(AC12>=Recall_Target*100)+(AF12=0)) | AJ12: =IF(B12="","",(R12<=Budget)+(U12<Deaths_Appetite)+(X12<=Carbon_Budget)+(AA12=0)+(AD12>=Recall_Target*100)+(AG12=0))
A13: =IF(B13="","","S"&TEXT(ROW()-4,"00")) | AH13: =IF(B13="","",(R13<=Budget)+(S13<Deaths_Appetite)+(V13<=Carbon_Budget)+(Y13=0)+(AB13>=Recall_Target*100)+(AE13=0)) | AI13: =IF(B13="","",(R13<=Budget)+(T13<Deaths_Appetite)+(W13<=Carbon_Budget)+(Z13=0)+(AC13>=Recall_Target*100)+(AF13=0)) | AJ13: =IF(B13="","",(R13<=Budget)+(U13<Deaths_Appetite)+(X13<=Carbon_Budget)+(AA13=0)+(AD13>=Recall_Target*100)+(AG13=0))
A14: =IF(B14="","","S"&TEXT(ROW()-4,"00")) | AH14: =IF(B14="","",(R14<=Budget)+(S14<Deaths_Appetite)+(V14<=Carbon_Budget)+(Y14=0)+(AB14>=Recall_Target*100)+(AE14=0)) | AI14: =IF(B14="","",(R14<=Budget)+(T14<Deaths_Appetite)+(W14<=Carbon_Budget)+(Z14=0)+(AC14>=Recall_Target*100)+(AF14=0)) | AJ14: =IF(B14="","",(R14<=Budget)+(U14<Deaths_Appetite)+(X14<=Carbon_Budget)+(AA14=0)+(AD14>=Recall_Target*100)+(AG14=0))
A15: =IF(B15="","","S"&TEXT(ROW()-4,"00")) | AH15: =IF(B15="","",(R15<=Budget)+(S15<Deaths_Appetite)+(V15<=Carbon_Budget)+(Y15=0)+(AB15>=Recall_Target*100)+(AE15=0)) | AI15: =IF(B15="","",(R15<=Budget)+(T15<Deaths_Appetite)+(W15<=Carbon_Budget)+(Z15=0)+(AC15>=Recall_Target*100)+(AF15=0)) | AJ15: =IF(B15="","",(R15<=Budget)+(U15<Deaths_Appetite)+(X15<=Carbon_Budget)+(AA15=0)+(AD15>=Recall_Target*100)+(AG15=0))
A16: =IF(B16="","","S"&TEXT(ROW()-4,"00")) | AH16: =IF(B16="","",(R16<=Budget)+(S16<Deaths_Appetite)+(V16<=Carbon_Budget)+(Y16=0)+(AB16>=Recall_Target*100)+(AE16=0)) | AI16: =IF(B16="","",(R16<=Budget)+(T16<Deaths_Appetite)+(W16<=Carbon_Budget)+(Z16=0)+(AC16>=Recall_Target*100)+(AF16=0)) | AJ16: =IF(B16="","",(R16<=Budget)+(U16<Deaths_Appetite)+(X16<=Carbon_Budget)+(AA16=0)+(AD16>=Recall_Target*100)+(AG16=0))
A17: =IF(B17="","","S"&TEXT(ROW()-4,"00")) | AH17: =IF(B17="","",(R17<=Budget)+(S17<Deaths_Appetite)+(V17<=Carbon_Budget)+(Y17=0)+(AB17>=Recall_Target*100)+(AE17=0)) | AI17: =IF(B17="","",(R17<=Budget)+(T17<Deaths_Appetite)+(W17<=Carbon_Budget)+(Z17=0)+(AC17>=Recall_Target*100)+(AF17=0)) | AJ17: =IF(B17="","",(R17<=Budget)+(U17<Deaths_Appetite)+(X17<=Carbon_Budget)+(AA17=0)+(AD17>=Recall_Target*100)+(AG17=0))
A18: =IF(B18="","","S"&TEXT(ROW()-4,"00")) | AH18: =IF(B18="","",(R18<=Budget)+(S18<Deaths_Appetite)+(V18<=Carbon_Budget)+(Y18=0)+(AB18>=Recall_Target*100)+(AE18=0)) | AI18: =IF(B18="","",(R18<=Budget)+(T18<Deaths_Appetite)+(W18<=Carbon_Budget)+(Z18=0)+(AC18>=Recall_Target*100)+(AF18=0)) | AJ18: =IF(B18="","",(R18<=Budget)+(U18<Deaths_Appetite)+(X18<=Carbon_Budget)+(AA18=0)+(AD18>=Recall_Target*100)+(AG18=0))
... A204: =IF(B204="","","S"&TEXT(ROW()-4,"00")) | AH204: =IF(B204="","",(R204<=Budget)+(S204<Deaths_Appetite)+(V204<=Carbon_Budget)+(Y204=0)+(AB204>=Recall_Target*100)+(AE204=0)) | AI204: =IF(B204="","",(R204<=Budget)+(T204<Deaths_Appetite)+(W204<=Carbon_Budget)+(Z204=0)+(AC204>=Recall_Target*100)+(AF204=0)) | AJ204: =IF(B204="","",(R204<=Budget)+(U204<Deaths_Appetite)+(X204<=Carbon_Budget)+(AA204=0)+(AD204>=Recall_Target*100)+(AG204=0))

Sheet Decision_Matrix
A1: Decision_Matrix — shortlist, score, vote and decide
A2: 1) Agree weights. 2) Shortlist up to five scenario IDs from Scenario_Log. 3) Each member votes. 4) Record the decision, the target you relax and the dissent.
B4: 1. Board targets and your group's weights
B5: Board target | C5: Limit | D5: Weight (0–5) | F5: Warming | G5: Weight
B6: Excess deaths (London-wide) | C6: ="< "&Deaths_Appetite -> < 150 | D6: 1 | F6: +0°C | G6: 0.5 | I6: Limits come from the Control_Panel risk-appetite cells. Weights are a group decision: say why in your recommendation.
B7: Portfolio cost £m | C7: ="≤ "&Budget -> ≤ 50 | D7: 1 | F7: +1°C | G7: 0.3
B8: Cooling carbon tCO₂e | C8: ="≤ "&TEXT(Carbon_Budget,"#,##0") -> ≤ 20,000 | D8: 1 | F8: +2°C | G8: 0.2
B9: Representation gap days | C9: ="0" -> 0 | D9: 1 | F9: Total | G9: =SUM(G6:G8) -> 1
B10: AI hot-day recall % | C10: ="≥ "&Recall_Target*100 -> ≥ 80 | D10: 1
B11: Tipping days | C11: ="0" -> 0 | D11: 1
B13: 2. Shortlist (up to five scenarios)
B14: Scenario ID | C14: Name | D14: Recorded by | E14: Mitigation | F14: Cost £m | G14: Deaths +0 | H14: Deaths +1 | I14: Deaths +2 | J14: Carbon +0 | K14: Carbon +1 | L14: Carbon +2 | M14: Gap +0 | N14: Gap +1 | O14: Gap +2 | P14: Recall +0 | Q14: Recall +1 | R14: Recall +2 | S14: Tipping +0 | T14: Tipping +1 | U14: Tipping +2 | V14: Met +0 | W14: Met +1 | X14: Met +2 | Y14: Weighted score | Z14: Votes | AA14: Rank
B15: S01 | C15: =IF($B15="","",IFERROR(INDEX(Scenario_Log!$C$5:$C$204,MATCH($B15,Scenario_Log!$A$5:$A$204,0)),"ID not found")) -> Baseline: no portfolio | D15: =IF($B15="","",IFERROR(INDEX(Scenario_Log!$B$5:$B$204,MATCH($B15,Scenario_Log!$A$5:$A$204,0)),"ID not found")) -> Example | E15: =IF($B15="","",IFERROR(INDEX(Scenario_Log!$E$5:$E$204,MATCH($B15,Scenario_Log!$A$5:$A$204,0)),"ID not found")) -> Baseline | F15: =IF($B15="","",IFERROR(INDEX(Scenario_Log!$R$5:$R$204,MATCH($B15,Scenario_Log!$A$5:$A$204,0)),"ID not found")) -> 0 | G15: =IF($B15="","",IFERROR(INDEX(Scenario_Log!$S$5:$S$204,MATCH($B15,Scenario_Log!$A$5:$A$204,0)),"ID not found")) -> 387 | H15: =IF($B15="","",IFERROR(INDEX(Scenario_Log!$T$5:$T$204,MATCH($B15,Scenario_Log!$A$5:$A$204,0)),"ID not found")) -> 528 | I15: =IF($B15="","",IFERROR(INDEX(Scenario_Log!$U$5:$U$204,MATCH($B15,Scenario_Log!$A$5:$A$204,0)),"ID not found")) -> 695 | J15: =IF($B15="","",IFERROR(INDEX(Scenario_Log!$V$5:$V$204,MATCH($B15,Scenario_Log!$A$5:$A$204,0)),"ID not found")) -> 4160 | K15: =IF($B15="","",IFERROR(INDEX(Scenario_Log!$W$5:$W$204,MATCH($B15,Scenario_Log!$A$5:$A$204,0)),"ID not found")) -> 6016 | L15: =IF($B15="","",IFERROR(INDEX(Scenario_Log!$X$5:$X$204,MATCH($B15,Scenario_Log!$A$5:$A$204,0)),"ID not found")) -> 8466 | M15: =IF($B15="","",IFERROR(INDEX(Scenario_Log!$Y$5:$Y$204,MATCH($B15,Scenario_Log!$A$5:$A$204,0)),"ID not found")) -> 19 | N15: =IF($B15="","",IFERROR(INDEX(Scenario_Log!$Z$5:$Z$204,MATCH($B15,Scenario_Log!$A$5:$A$204,0)),"ID not found")) -> 15 | O15: =IF($B15="","",IFERROR(INDEX(Scenario_Log!$AA$5:$AA$204,MATCH($B15,Scenario_Log!$A$5:$A$204,0)),"ID not found")) -> 22 | P15: =IF($B15="","",IFERROR(INDEX(Scenario_Log!$AB$5:$AB$204,MATCH($B15,Scenario_Log!$A$5:$A$204,0)),"ID not found")) -> 37 | Q15: =IF($B15="","",IFERROR(INDEX(Scenario_Log!$AC$5:$AC$204,MATCH($B15,Scenario_Log!$A$5:$A$204,0)),"ID not found")) -> 36 | R15: =IF($B15="","",IFERROR(INDEX(Scenario_Log!$AD$5:$AD$204,MATCH($B15,Scenario_Log!$A$5:$A$204,0)),"ID not found")) -> 46 | S15: =IF($B15="","",IFERROR(INDEX(Scenario_Log!$AE$5:$AE$204,MATCH($B15,Scenario_Log!$A$5:$A$204,0)),"ID not found")) -> 3 | T15: =IF($B15="","",IFERROR(INDEX(Scenario_Log!$AF$5:$AF$204,MATCH($B15,Scenario_Log!$A$5:$A$204,0)),"ID not found")) -> 6 | U15: =IF($B15="","",IFERROR(INDEX(Scenario_Log!$AG$5:$AG$204,MATCH($B15,Scenario_Log!$A$5:$A$204,0)),"ID not found")) -> 10 | V15: =IF($B15="","",IFERROR((F15<=Budget)+(G15<Deaths_Appetite)+(J15<=Carbon_Budget)+(M15=0)+(P15>=Recall_Target*100)+(S15=0),"")) -> 2 | W15: =IF($B15="","",IFERROR((F15<=Budget)+(H15<Deaths_Appetite)+(K15<=Carbon_Budget)+(N15=0)+(Q15>=Recall_Target*100)+(T15=0),"")) -> 2 | X15: =IF($B15="","",IFERROR((F15<=Budget)+(I15<Deaths_Appetite)+(L15<=Carbon_Budget)+(O15=0)+(R15>=Recall_Target*100)+(U15=0),"")) -> 2 | Y15: =IF($B15="","",IFERROR(($G$6*($D$6*(G15<Deaths_Appetite)+$D$7*(F15<=Budget)+$D$8*(J15<=Carbon_Budget)+$D$9*(M15=0)+$D$10*(P15>=Recall_Target*100)+$D$11*(S15=0))+$G$7*($D$6*(H15<Deaths_Appetite)+$D$7*(F15<=Budget)+$D$8*(K15<=Carbon_Budget)+$D$9*(N15=0)+$D$10*(Q15>=Recall_Target*100)+$D$11*(T15=0))+$G$8*($D$6*(I15<Deaths_Appetite)+$D$7*(F15<=Budget)+$D$8*(L15<=Carbon_Budget)+$D$9*(O15=0)+$D$10*(R15>=Recall_Target*100)+$D$11*(U15=0)))/(SUM($D$6:$D$11)*$G$9),"")) -> 0.33333333 | Z15: =IF($B15="","",COUNTIF($D$24:$D$29,$B15)) -> 0 | AA15: =IF(OR($B15="",NOT(ISNUMBER(Y15))),"",RANK(Y15,$Y$15:$Y$19)) -> 1
B16: S02 | C16: =IF($B16="","",IFERROR(INDEX(Scenario_Log!$C$5:$C$204,MATCH($B16,Scenario_Log!$A$5:$A$204,0)),"ID not found")) -> Default portfolio: five measures at 50%, no AC | D16: =IF($B16="","",IFERROR(INDEX(Scenario_Log!$B$5:$B$204,MATCH($B16,Scenario_Log!$A$5:$A$204,0)),"ID not found")) -> Example | E16: =IF($B16="","",IFERROR(INDEX(Scenario_Log!$E$5:$E$204,MATCH($B16,Scenario_Log!$A$5:$A$204,0)),"ID not found")) -> With interventions | F16: =IF($B16="","",IFERROR(INDEX(Scenario_Log!$R$5:$R$204,MATCH($B16,Scenario_Log!$A$5:$A$204,0)),"ID not found")) -> 35.3 | G16: =IF($B16="","",IFERROR(INDEX(Scenario_Log!$S$5:$S$204,MATCH($B16,Scenario_Log!$A$5:$A$204,0)),"ID not found")) -> 292 | H16: =IF($B16="","",IFERROR(INDEX(Scenario_Log!$T$5:$T$204,MATCH($B16,Scenario_Log!$A$5:$A$204,0)),"ID not found")) -> 404 | I16: =IF($B16="","",IFERROR(INDEX(Scenario_Log!$U$5:$U$204,MATCH($B16,Scenario_Log!$A$5:$A$204,0)),"ID not found")) -> 541 | J16: =IF($B16="","",IFERROR(INDEX(Scenario_Log!$V$5:$V$204,MATCH($B16,Scenario_Log!$A$5:$A$204,0)),"ID not found")) -> 2413 | K16: =IF($B16="","",IFERROR(INDEX(Scenario_Log!$W$5:$W$204,MATCH($B16,Scenario_Log!$A$5:$A$204,0)),"ID not found")) -> 4082 | L16: =IF($B16="","",IFERROR(INDEX(Scenario_Log!$X$5:$X$204,MATCH($B16,Scenario_Log!$A$5:$A$204,0)),"ID not found")) -> 6294 | M16: =IF($B16="","",IFERROR(INDEX(Scenario_Log!$Y$5:$Y$204,MATCH($B16,Scenario_Log!$A$5:$A$204,0)),"ID not found")) -> 15 | N16: =IF($B16="","",IFERROR(INDEX(Scenario_Log!$Z$5:$Z$204,MATCH($B16,Scenario_Log!$A$5:$A$204,0)),"ID not found")) -> 6 | O16: =IF($B16="","",IFERROR(INDEX(Scenario_Log!$AA$5:$AA$204,MATCH($B16,Scenario_Log!$A$5:$A$204,0)),"ID not found")) -> 15 | P16: =IF($B16="","",IFERROR(INDEX(Scenario_Log!$AB$5:$AB$204,MATCH($B16,Scenario_Log!$A$5:$A$204,0)),"ID not found")) -> 65 | Q16: =IF($B16="","",IFERROR(INDEX(Scenario_Log!$AC$5:$AC$204,MATCH($B16,Scenario_Log!$A$5:$A$204,0)),"ID not found")) -> 66 | R16: =IF($B16="","",IFERROR(INDEX(Scenario_Log!$AD$5:$AD$204,MATCH($B16,Scenario_Log!$A$5:$A$204,0)),"ID not found")) -> 66 | S16: =IF($B16="","",IFERROR(INDEX(Scenario_Log!$AE$5:$AE$204,MATCH($B16,Scenario_Log!$A$5:$A$204,0)),"ID not found")) -> 1 | T16: =IF($B16="","",IFERROR(INDEX(Scenario_Log!$AF$5:$AF$204,MATCH($B16,Scenario_Log!$A$5:$A$204,0)),"ID not found")) -> 5 | U16: =IF($B16="","",IFERROR(INDEX(Scenario_Log!$AG$5:$AG$204,MATCH($B16,Scenario_Log!$A$5:$A$204,0)),"ID not found")) -> 8 | V16: =IF($B16="","",IFERROR((F16<=Budget)+(G16<Deaths_Appetite)+(J16<=Carbon_Budget)+(M16=0)+(P16>=Recall_Target*100)+(S16=0),"")) -> 2 | W16: =IF($B16="","",IFERROR((F16<=Budget)+(H16<Deaths_Appetite)+(K16<=Carbon_Budget)+(N16=0)+(Q16>=Recall_Target*100)+(T16=0),"")) -> 2 | X16: =IF($B16="","",IFERROR((F16<=Budget)+(I16<Deaths_Appetite)+(L16<=Carbon_Budget)+(O16=0)+(R16>=Recall_Target*100)+(U16=0),"")) -> 2 | Y16: =IF($B16="","",IFERROR(($G$6*($D$6*(G16<Deaths_Appetite)+$D$7*(F16<=Budget)+$D$8*(J16<=Carbon_Budget)+$D$9*(M16=0)+$D$10*(P16>=Recall_Target*100)+$D$11*(S16=0))+$G$7*($D$6*(H16<Deaths_Appetite)+$D$7*(F16<=Budget)+$D$8*(K16<=Carbon_Budget)+$D$9*(N16=0)+$D$10*(Q16>=Recall_Target*100)+$D$11*(T16=0))+$G$8*($D$6*(I16<Deaths_Appetite)+$D$7*(F16<=Budget)+$D$8*(L16<=Carbon_Budget)+$D$9*(O16=0)+$D$10*(R16>=Recall_Target*100)+$D$11*(U16=0)))/(SUM($D$6:$D$11)*$G$9),"")) -> 0.33333333 | Z16: =IF($B16="","",COUNTIF($D$24:$D$29,$B16)) -> 0 | AA16: =IF(OR($B16="",NOT(ISNUMBER(Y16))),"",RANK(Y16,$Y$15:$Y$19)) -> 1
C17: =IF($B17="","",IFERROR(INDEX(Scenario_Log!$C$5:$C$204,MATCH($B17,Scenario_Log!$A$5:$A$204,0)),"ID not found")) | D17: =IF($B17="","",IFERROR(INDEX(Scenario_Log!$B$5:$B$204,MATCH($B17,Scenario_Log!$A$5:$A$204,0)),"ID not found")) | E17: =IF($B17="","",IFERROR(INDEX(Scenario_Log!$E$5:$E$204,MATCH($B17,Scenario_Log!$A$5:$A$204,0)),"ID not found")) | F17: =IF($B17="","",IFERROR(INDEX(Scenario_Log!$R$5:$R$204,MATCH($B17,Scenario_Log!$A$5:$A$204,0)),"ID not found")) | G17: =IF($B17="","",IFERROR(INDEX(Scenario_Log!$S$5:$S$204,MATCH($B17,Scenario_Log!$A$5:$A$204,0)),"ID not found")) | H17: =IF($B17="","",IFERROR(INDEX(Scenario_Log!$T$5:$T$204,MATCH($B17,Scenario_Log!$A$5:$A$204,0)),"ID not found")) | I17: =IF($B17="","",IFERROR(INDEX(Scenario_Log!$U$5:$U$204,MATCH($B17,Scenario_Log!$A$5:$A$204,0)),"ID not found")) | J17: =IF($B17="","",IFERROR(INDEX(Scenario_Log!$V$5:$V$204,MATCH($B17,Scenario_Log!$A$5:$A$204,0)),"ID not found")) | K17: =IF($B17="","",IFERROR(INDEX(Scenario_Log!$W$5:$W$204,MATCH($B17,Scenario_Log!$A$5:$A$204,0)),"ID not found")) | L17: =IF($B17="","",IFERROR(INDEX(Scenario_Log!$X$5:$X$204,MATCH($B17,Scenario_Log!$A$5:$A$204,0)),"ID not found")) | M17: =IF($B17="","",IFERROR(INDEX(Scenario_Log!$Y$5:$Y$204,MATCH($B17,Scenario_Log!$A$5:$A$204,0)),"ID not found")) | N17: =IF($B17="","",IFERROR(INDEX(Scenario_Log!$Z$5:$Z$204,MATCH($B17,Scenario_Log!$A$5:$A$204,0)),"ID not found")) | O17: =IF($B17="","",IFERROR(INDEX(Scenario_Log!$AA$5:$AA$204,MATCH($B17,Scenario_Log!$A$5:$A$204,0)),"ID not found")) | P17: =IF($B17="","",IFERROR(INDEX(Scenario_Log!$AB$5:$AB$204,MATCH($B17,Scenario_Log!$A$5:$A$204,0)),"ID not found")) | Q17: =IF($B17="","",IFERROR(INDEX(Scenario_Log!$AC$5:$AC$204,MATCH($B17,Scenario_Log!$A$5:$A$204,0)),"ID not found")) | R17: =IF($B17="","",IFERROR(INDEX(Scenario_Log!$AD$5:$AD$204,MATCH($B17,Scenario_Log!$A$5:$A$204,0)),"ID not found")) | S17: =IF($B17="","",IFERROR(INDEX(Scenario_Log!$AE$5:$AE$204,MATCH($B17,Scenario_Log!$A$5:$A$204,0)),"ID not found")) | T17: =IF($B17="","",IFERROR(INDEX(Scenario_Log!$AF$5:$AF$204,MATCH($B17,Scenario_Log!$A$5:$A$204,0)),"ID not found")) | U17: =IF($B17="","",IFERROR(INDEX(Scenario_Log!$AG$5:$AG$204,MATCH($B17,Scenario_Log!$A$5:$A$204,0)),"ID not found")) | V17: =IF($B17="","",IFERROR((F17<=Budget)+(G17<Deaths_Appetite)+(J17<=Carbon_Budget)+(M17=0)+(P17>=Recall_Target*100)+(S17=0),"")) | W17: =IF($B17="","",IFERROR((F17<=Budget)+(H17<Deaths_Appetite)+(K17<=Carbon_Budget)+(N17=0)+(Q17>=Recall_Target*100)+(T17=0),"")) | X17: =IF($B17="","",IFERROR((F17<=Budget)+(I17<Deaths_Appetite)+(L17<=Carbon_Budget)+(O17=0)+(R17>=Recall_Target*100)+(U17=0),"")) | Y17: =IF($B17="","",IFERROR(($G$6*($D$6*(G17<Deaths_Appetite)+$D$7*(F17<=Budget)+$D$8*(J17<=Carbon_Budget)+$D$9*(M17=0)+$D$10*(P17>=Recall_Target*100)+$D$11*(S17=0))+$G$7*($D$6*(H17<Deaths_Appetite)+$D$7*(F17<=Budget)+$D$8*(K17<=Carbon_Budget)+$D$9*(N17=0)+$D$10*(Q17>=Recall_Target*100)+$D$11*(T17=0))+$G$8*($D$6*(I17<Deaths_Appetite)+$D$7*(F17<=Budget)+$D$8*(L17<=Carbon_Budget)+$D$9*(O17=0)+$D$10*(R17>=Recall_Target*100)+$D$11*(U17=0)))/(SUM($D$6:$D$11)*$G$9),"")) | Z17: =IF($B17="","",COUNTIF($D$24:$D$29,$B17)) | AA17: =IF(OR($B17="",NOT(ISNUMBER(Y17))),"",RANK(Y17,$Y$15:$Y$19))
C18: =IF($B18="","",IFERROR(INDEX(Scenario_Log!$C$5:$C$204,MATCH($B18,Scenario_Log!$A$5:$A$204,0)),"ID not found")) | D18: =IF($B18="","",IFERROR(INDEX(Scenario_Log!$B$5:$B$204,MATCH($B18,Scenario_Log!$A$5:$A$204,0)),"ID not found")) | E18: =IF($B18="","",IFERROR(INDEX(Scenario_Log!$E$5:$E$204,MATCH($B18,Scenario_Log!$A$5:$A$204,0)),"ID not found")) | F18: =IF($B18="","",IFERROR(INDEX(Scenario_Log!$R$5:$R$204,MATCH($B18,Scenario_Log!$A$5:$A$204,0)),"ID not found")) | G18: =IF($B18="","",IFERROR(INDEX(Scenario_Log!$S$5:$S$204,MATCH($B18,Scenario_Log!$A$5:$A$204,0)),"ID not found")) | H18: =IF($B18="","",IFERROR(INDEX(Scenario_Log!$T$5:$T$204,MATCH($B18,Scenario_Log!$A$5:$A$204,0)),"ID not found")) | I18: =IF($B18="","",IFERROR(INDEX(Scenario_Log!$U$5:$U$204,MATCH($B18,Scenario_Log!$A$5:$A$204,0)),"ID not found")) | J18: =IF($B18="","",IFERROR(INDEX(Scenario_Log!$V$5:$V$204,MATCH($B18,Scenario_Log!$A$5:$A$204,0)),"ID not found")) | K18: =IF($B18="","",IFERROR(INDEX(Scenario_Log!$W$5:$W$204,MATCH($B18,Scenario_Log!$A$5:$A$204,0)),"ID not found")) | L18: =IF($B18="","",IFERROR(INDEX(Scenario_Log!$X$5:$X$204,MATCH($B18,Scenario_Log!$A$5:$A$204,0)),"ID not found")) | M18: =IF($B18="","",IFERROR(INDEX(Scenario_Log!$Y$5:$Y$204,MATCH($B18,Scenario_Log!$A$5:$A$204,0)),"ID not found")) | N18: =IF($B18="","",IFERROR(INDEX(Scenario_Log!$Z$5:$Z$204,MATCH($B18,Scenario_Log!$A$5:$A$204,0)),"ID not found")) | O18: =IF($B18="","",IFERROR(INDEX(Scenario_Log!$AA$5:$AA$204,MATCH($B18,Scenario_Log!$A$5:$A$204,0)),"ID not found")) | P18: =IF($B18="","",IFERROR(INDEX(Scenario_Log!$AB$5:$AB$204,MATCH($B18,Scenario_Log!$A$5:$A$204,0)),"ID not found")) | Q18: =IF($B18="","",IFERROR(INDEX(Scenario_Log!$AC$5:$AC$204,MATCH($B18,Scenario_Log!$A$5:$A$204,0)),"ID not found")) | R18: =IF($B18="","",IFERROR(INDEX(Scenario_Log!$AD$5:$AD$204,MATCH($B18,Scenario_Log!$A$5:$A$204,0)),"ID not found")) | S18: =IF($B18="","",IFERROR(INDEX(Scenario_Log!$AE$5:$AE$204,MATCH($B18,Scenario_Log!$A$5:$A$204,0)),"ID not found")) | T18: =IF($B18="","",IFERROR(INDEX(Scenario_Log!$AF$5:$AF$204,MATCH($B18,Scenario_Log!$A$5:$A$204,0)),"ID not found")) | U18: =IF($B18="","",IFERROR(INDEX(Scenario_Log!$AG$5:$AG$204,MATCH($B18,Scenario_Log!$A$5:$A$204,0)),"ID not found")) | V18: =IF($B18="","",IFERROR((F18<=Budget)+(G18<Deaths_Appetite)+(J18<=Carbon_Budget)+(M18=0)+(P18>=Recall_Target*100)+(S18=0),"")) | W18: =IF($B18="","",IFERROR((F18<=Budget)+(H18<Deaths_Appetite)+(K18<=Carbon_Budget)+(N18=0)+(Q18>=Recall_Target*100)+(T18=0),"")) | X18: =IF($B18="","",IFERROR((F18<=Budget)+(I18<Deaths_Appetite)+(L18<=Carbon_Budget)+(O18=0)+(R18>=Recall_Target*100)+(U18=0),"")) | Y18: =IF($B18="","",IFERROR(($G$6*($D$6*(G18<Deaths_Appetite)+$D$7*(F18<=Budget)+$D$8*(J18<=Carbon_Budget)+$D$9*(M18=0)+$D$10*(P18>=Recall_Target*100)+$D$11*(S18=0))+$G$7*($D$6*(H18<Deaths_Appetite)+$D$7*(F18<=Budget)+$D$8*(K18<=Carbon_Budget)+$D$9*(N18=0)+$D$10*(Q18>=Recall_Target*100)+$D$11*(T18=0))+$G$8*($D$6*(I18<Deaths_Appetite)+$D$7*(F18<=Budget)+$D$8*(L18<=Carbon_Budget)+$D$9*(O18=0)+$D$10*(R18>=Recall_Target*100)+$D$11*(U18=0)))/(SUM($D$6:$D$11)*$G$9),"")) | Z18: =IF($B18="","",COUNTIF($D$24:$D$29,$B18)) | AA18: =IF(OR($B18="",NOT(ISNUMBER(Y18))),"",RANK(Y18,$Y$15:$Y$19))
C19: =IF($B19="","",IFERROR(INDEX(Scenario_Log!$C$5:$C$204,MATCH($B19,Scenario_Log!$A$5:$A$204,0)),"ID not found")) | D19: =IF($B19="","",IFERROR(INDEX(Scenario_Log!$B$5:$B$204,MATCH($B19,Scenario_Log!$A$5:$A$204,0)),"ID not found")) | E19: =IF($B19="","",IFERROR(INDEX(Scenario_Log!$E$5:$E$204,MATCH($B19,Scenario_Log!$A$5:$A$204,0)),"ID not found")) | F19: =IF($B19="","",IFERROR(INDEX(Scenario_Log!$R$5:$R$204,MATCH($B19,Scenario_Log!$A$5:$A$204,0)),"ID not found")) | G19: =IF($B19="","",IFERROR(INDEX(Scenario_Log!$S$5:$S$204,MATCH($B19,Scenario_Log!$A$5:$A$204,0)),"ID not found")) | H19: =IF($B19="","",IFERROR(INDEX(Scenario_Log!$T$5:$T$204,MATCH($B19,Scenario_Log!$A$5:$A$204,0)),"ID not found")) | I19: =IF($B19="","",IFERROR(INDEX(Scenario_Log!$U$5:$U$204,MATCH($B19,Scenario_Log!$A$5:$A$204,0)),"ID not found")) | J19: =IF($B19="","",IFERROR(INDEX(Scenario_Log!$V$5:$V$204,MATCH($B19,Scenario_Log!$A$5:$A$204,0)),"ID not found")) | K19: =IF($B19="","",IFERROR(INDEX(Scenario_Log!$W$5:$W$204,MATCH($B19,Scenario_Log!$A$5:$A$204,0)),"ID not found")) | L19: =IF($B19="","",IFERROR(INDEX(Scenario_Log!$X$5:$X$204,MATCH($B19,Scenario_Log!$A$5:$A$204,0)),"ID not found")) | M19: =IF($B19="","",IFERROR(INDEX(Scenario_Log!$Y$5:$Y$204,MATCH($B19,Scenario_Log!$A$5:$A$204,0)),"ID not found")) | N19: =IF($B19="","",IFERROR(INDEX(Scenario_Log!$Z$5:$Z$204,MATCH($B19,Scenario_Log!$A$5:$A$204,0)),"ID not found")) | O19: =IF($B19="","",IFERROR(INDEX(Scenario_Log!$AA$5:$AA$204,MATCH($B19,Scenario_Log!$A$5:$A$204,0)),"ID not found")) | P19: =IF($B19="","",IFERROR(INDEX(Scenario_Log!$AB$5:$AB$204,MATCH($B19,Scenario_Log!$A$5:$A$204,0)),"ID not found")) | Q19: =IF($B19="","",IFERROR(INDEX(Scenario_Log!$AC$5:$AC$204,MATCH($B19,Scenario_Log!$A$5:$A$204,0)),"ID not found")) | R19: =IF($B19="","",IFERROR(INDEX(Scenario_Log!$AD$5:$AD$204,MATCH($B19,Scenario_Log!$A$5:$A$204,0)),"ID not found")) | S19: =IF($B19="","",IFERROR(INDEX(Scenario_Log!$AE$5:$AE$204,MATCH($B19,Scenario_Log!$A$5:$A$204,0)),"ID not found")) | T19: =IF($B19="","",IFERROR(INDEX(Scenario_Log!$AF$5:$AF$204,MATCH($B19,Scenario_Log!$A$5:$A$204,0)),"ID not found")) | U19: =IF($B19="","",IFERROR(INDEX(Scenario_Log!$AG$5:$AG$204,MATCH($B19,Scenario_Log!$A$5:$A$204,0)),"ID not found")) | V19: =IF($B19="","",IFERROR((F19<=Budget)+(G19<Deaths_Appetite)+(J19<=Carbon_Budget)+(M19=0)+(P19>=Recall_Target*100)+(S19=0),"")) | W19: =IF($B19="","",IFERROR((F19<=Budget)+(H19<Deaths_Appetite)+(K19<=Carbon_Budget)+(N19=0)+(Q19>=Recall_Target*100)+(T19=0),"")) | X19: =IF($B19="","",IFERROR((F19<=Budget)+(I19<Deaths_Appetite)+(L19<=Carbon_Budget)+(O19=0)+(R19>=Recall_Target*100)+(U19=0),"")) | Y19: =IF($B19="","",IFERROR(($G$6*($D$6*(G19<Deaths_Appetite)+$D$7*(F19<=Budget)+$D$8*(J19<=Carbon_Budget)+$D$9*(M19=0)+$D$10*(P19>=Recall_Target*100)+$D$11*(S19=0))+$G$7*($D$6*(H19<Deaths_Appetite)+$D$7*(F19<=Budget)+$D$8*(K19<=Carbon_Budget)+$D$9*(N19=0)+$D$10*(Q19>=Recall_Target*100)+$D$11*(T19=0))+$G$8*($D$6*(I19<Deaths_Appetite)+$D$7*(F19<=Budget)+$D$8*(L19<=Carbon_Budget)+$D$9*(O19=0)+$D$10*(R19>=Recall_Target*100)+$D$11*(U19=0)))/(SUM($D$6:$D$11)*$G$9),"")) | Z19: =IF($B19="","",COUNTIF($D$24:$D$29,$B19)) | AA19: =IF(OR($B19="",NOT(ISNUMBER(Y19))),"",RANK(Y19,$Y$15:$Y$19))
B20: No scenario meets every target at +2°C: the weighted score shows which trade-off your weights favour, not the right answer.
B22: 3. Group vote
B23: Member (initials) | C23: Role this round | D23: Vote (scenario ID) | E23: Why
B31: 4. Decision
B32: Chosen scenario ID
B33: Chosen scenario name | C33: =IF(C32="","",IFERROR(INDEX(Scenario_Log!$C$5:$C$204,MATCH(C32,Scenario_Log!$A$5:$A$204,0)),"ID not found"))
B34: Target we recommend relaxing
B35: Why this trade-off
B36: Residual risk and who carries it
B37: Copilot challenge: strongest objection and our response
B39: 5. Dissent log (at least two entries)
B40: Who | C40: Disagreed about | D40: Evidence tested in the dashboard | G40: How it was resolved

Sheet Control_Panel
A1: Control Panel — what-if levers (Project HEATWISE)
A2: Blue text on yellow = inputs you change. Black = formulas. Green = links from other sheets. Every output in the workbook recalculates from these levers.
B4: A. Scenario | G4: Live monitoring dashboard (selected year and area)
B5: Monitoring year (1979–2023) | C5: 2022 | D5: year | E5: 2022 = July heat dome (40.2°C recorded at Heathrow on 18 Jul in this series). | G5: Key risk indicator | H5: Value | I5: Status
B6: Neighbourhood typology monitored | C6: Inner London: dense, low green | E6: Drives the urban heat island (UHI) uplift applied to the reference station. Edit uplifts on Equity_Lens. | G6: Hot days | H6: =KPI_HotDays -> 41
B7: Mitigation scenario | C7: Baseline | E7: 'With interventions' applies the levels set on the Optimise sheet. | G7: Heatwave days (Met Office-style) | H7: =KPI_HWDays -> 21 | I7: =IF(KPI_HWDays>0,"RED","GREEN") -> RED
B8: Climate shift added to observations | C8: 0 | D8: °C | E8: What-if warming applied uniformly. Try 0.5–3.0 to probe tipping points. | G8: Longest hot-day run | H8: =KPI_MaxRun -> 9
B9: B. Hazard thresholds (key risk indicators) | G9: Warm nights (no recovery) | H9: =KPI_WarmNights -> 64 | I9: =IF(KPI_WarmNights>=10,"RED",IF(KPI_WarmNights>=3,"AMBER","GREEN")) -> RED
B10: Hot-day threshold (daily max) | C10: 28 | D10: °C | E10: Met Office heatwave threshold for London = 28°C on ≥3 consecutive days. | G10: Amber-or-red alert days | H10: =KPI_Amber -> 19 | I10: =IF(KPI_Red>0,"RED",IF(KPI_Amber>0,"AMBER","GREEN")) -> RED
B11: Consecutive hot days that define a heatwave | C11: 3 | D11: days | E11: Met Office definition: at least three consecutive days. | G11: Peak adjusted daily max °C | H11: =KPI_PeakTX -> 42.2
B12: Warm-night threshold (daily min) | C12: 18 | D12: °C | E12: Assumption: commonly cited legacy London night threshold — verify and justify. | G12: Peak heat-stress stock (°C·days) | H12: =KPI_PeakStock -> 45.575094 | I12: =IF(KPI_TipDays>0,"RED",IF(KPI_PeakStock>0.75*Capacity,"AMBER","GREEN")) -> RED
B13: Red-alert daily max (with warm night) | C13: 35 | D13: °C | E13: Teaching assumption: UKHSA alerts are impact-based, not a single temperature. | G13: Tipping days (capacity exceeded) | H13: =KPI_TipDays -> 3 | I13: =IF(KPI_TipDays>0,"RED","GREEN") -> RED
B14: Mean-temperature threshold for heat mortality | C14: 20 | D14: °C | E14: UKHSA defines heat episodes partly by mean CET ≥ 20°C. Used here for the exposure–response model. | G14: First tipping date | H14: =First_Tip -> 44760
B15: C. Data quality | G15: London-wide excess deaths (model) | H15: =London_Deaths -> 387 | I15: =IF(London_Deaths>Deaths_Appetite,"RED",IF(London_Deaths>0.75*Deaths_Appetite,"AMBER","GREEN")) -> RED
B16: Suspect-observation policy | C16: Use raw | E16: Use raw | Exclude suspect | Impute with model. Suspect = ECA&D flag ≠ 0 or TX < TG. | G16: Suspect observations on hot/warm days | H16: =KPI_SuspectHot -> 5 | I16: =IF(KPI_SuspectHot>0,"AMBER","GREEN") -> AMBER
B17: Injected sensor drift | C17: 0 | D17: °C/30d | E17: Simulates a degrading thermometer (data drift). 0 = off. Try 1.0. | G17: AI drift-alarm events | H17: =KPI_DriftDays -> 2 | I17: =IF(KPI_DriftDays>1,"RED",IF(KPI_DriftDays=1,"AMBER","GREEN")) -> RED
B18: Sensor drift starts on season day | C18: 60 | D18: day | E18: Day 1 = 1 May; day 62 = 1 July; day 79 = 18 July. | G18: First drift alarm | H18: =First_Drift -> 44760
B19: D. AI forecasting model and drift monitoring | G19: AI hot-day recall | H19: =KPI_Recall -> 0.36585366 | I19: =IF(ISNUMBER(KPI_Recall),IF(KPI_Recall<Recall_Target,"RED","GREEN"),"n/a") -> RED
B20: Training window start year | C20: 1979 | D20: year | E20: Model: next-day max temperature from today's max and sea-level pressure (OLS). | G20: AI missed hot days | H20: =KPI_Misses -> 26
B21: Training window end year | C21: 1998 | D21: year | E21: An old window bakes in a cooler climate → concept drift. | G21: Test year inside training window? (leak) | H21: =Leak_Flag -> 0 | I21: =IF(Leak_Flag=1,"AMBER","GREEN") -> GREEN
B22: CUSUM allowance k | C22: 1 | D22: °C | E22: Slack per day before bias accumulates. Calibrated: ~0.5 false alarms per summer in-sample. | G22: Representation-gap days | H22: =KPI_RepGap -> 19 | I22: =IF(KPI_RepGap>0,"RED","GREEN") -> RED
B23: CUSUM decision interval h | C23: 15 | D23: °C | E23: Alarm when cumulative bias exceeds h; CUSUM resets after each alarm. | G23: Cooling carbon tCO₂e (scenario) | H23: =Carbon_Now -> 4160.2612 | I23: =IF(Carbon_Now>Carbon_Budget,"RED","GREEN") -> GREEN
B24: Rolling 7-day MAE tolerance | C24: 4.5 | D24: °C | E24: Alarm when the model's recent error exceeds tolerance (typical MAE ≈ 2°C). | G24: Requirement change requests raised | H24: =Req_CR_Count -> 7 | I24: =IF(Req_CR_Count>0,"AMBER","GREEN") -> AMBER
B25: Required hot-day recall of the AI alert | C25: 0.8 | E25: Share of actual hot days the model must flag (missed alerts harm people).
B26: E. Tipping-point model (stock and flow of heat stress)
B27: Daytime heat-load threshold | C27: 25 | D27: °C | E27: Inflow to the heat-stress stock = max(0, TX_adj − this).
B28: Night-time recovery rate | C28: 0.5 | D28: per °C | E28: Extra outflow = rate × max(0, T_Night − TN_adj). Warm nights → no extra recovery.
B29: Baseline daily recovery (decay) | C29: 0.2 | D29: fraction/day | E29: Share of the stock that dissipates each day. Calibrated so inner London tips only in extreme summers (2003, 2020, 2022).
B30: System capacity (tipping threshold) | C30: 40 | D30: °C·days | E30: Stock above this = services overwhelmed (tipping). Teaching calibration — challenge it.
B31: Steepness of failure curve | C31: 0.15 | E31: P(failure) = 1/(1+exp(−k·(stock − capacity))).
B32: F. Health model calibration
B33: Calibration target: London excess deaths | C33: 387 | D33: deaths | E33: UKHSA Heat mortality monitoring report 2022: London total 387 (95% CI 158–615).
B34: Calibration year | C34: 2022 | D34: year | E34: β is re-derived so the reference-climate model reproduces the target.
B35: G. Risk appetite and constraints
B36: Excess-death appetite (London, per summer) | C36: 150 | D36: deaths | E36: Programme board appetite. Group decision — justify it.
B37: Cooling carbon budget | C37: 20000 | D37: tCO₂e | E37: Net cooling-related emissions allowed per summer.
B38: Intervention budget | C38: 50 | D38: £m | E38: Capital + annual revenue envelope for the Optimise sheet.
B40: H. Derived values (formulas — do not edit)
B41: Base daytime UHI uplift (selected typology) | C41: =INDEX(Equity_Lens!$C$6:$C$9,MATCH(Typology,Equity_Lens!$B$6:$B$9,0)) -> 2 | D41: °C
B42: Base night-time UHI uplift | C42: =INDEX(Equity_Lens!$D$6:$D$9,MATCH(Typology,Equity_Lens!$B$6:$B$9,0)) -> 4 | D42: °C
...

Sheet Monitor_Control
A1: Monitor_Control — step 4 of risk management as a live feedback loop
A2: Each day: observe → quality-check → compare with thresholds and model → detect drift and tipping → recommend control action → raise requirement change. Scroll right for AI drift columns.
A3: Year: | B3: =SelYear -> 2022 | D3: Hot days | F3: Warm nights | H3: Heatwave days | J3: Longest hot run | L3: Amber+ days | N3: Red days | P3: Peak TX adjusted °C | R3: Peak heat-stress stock
A4: Area: | B4: =Typology -> Inner London: dense, low green | D4: =SUM(N9:N161) -> 41 | F4: =SUM(O9:O161) -> 64 | H4: =SUM(Q9:Q161) -> 21 | J4: =MAX(P9:P161) -> 9 | L4: =COUNTIF(S9:S161,">=2") -> 19 | N4: =COUNTIF(S9:S161,3) -> 6 | P4: =MAX(I9:I161) -> 42.2 | R4: =MAX(T9:T161) -> 45.575094
A5: QA: | B5: =QA_Policy -> Use raw | D5: Tipping days | F5: Suspect obs on hot/warm days | H5: Drift-alarm events | J5: AI hot-day recall | L5: AI missed hot days | N5: AI false alarms | P5: Representation-gap days | R5: Excess deaths (this typology)
D6: =SUM(U9:U161) -> 3 | F6: =SUMPRODUCT((E9:E161=1)*(((N9:N161)+(O9:O161))>0)) -> 5 | H6: =SUMPRODUCT((AD9:AD161=1)*(AD8:AD160<>1)) -> 2 | J6: =IFERROR(COUNTIF(AF9:AF161,"Hit")/(COUNTIF(AF9:AF161,"Hit")+COUNTIF(AF9:AF161,"Miss")),"n/a") -> 0.36585366 | L6: =COUNTIF(AF9:AF161,"Miss") -> 26 | N6: =COUNTIF(AF9:AF161,"False alarm") -> 1 | P6: =SUM(AH9:AH161) -> 19 | R6: =SUM(W9:W161) -> 186.94633
A7: Time | D7: 1. OBSERVE & QUALITY-CHECK | N7: 2. COMPARE WITH THRESHOLDS | T7: 3. TIPPING POINT & IMPACT | X7: 4. AI MODEL MONITORING (DRIFT, RECALL, EQUITY) | AI7: 5. CONTROL
A8: Day | B8: Data row | C8: Date | D8: TX observed °C | E8: Suspect obs | F8: Model forecast (raw) °C | G8: Injected sensor drift °C | H8: TX used (after QA) °C | I8: TX adjusted °C | J8: TN observed °C | K8: TN adjusted °C | L8: TG observed °C | M8: TG adjusted °C | N8: Hot day | O8: Warm night | P8: Hot-day run | Q8: Heatwave day | R8: Alert level | S8: Alert score | T8: Heat-stress stock °C·d | U8: Tipping (stock > capacity) | V8: P(service failure) | W8: Excess deaths (this typology) | X8: Model forecast (adjusted) °C | Y8: Residual °C | Z8: |Residual| °C | AA8: Rolling 7-day MAE °C | AB8: CUSUM+ (under-forecast) | AC8: CUSUM− (over-forecast) | AD8: Drift alarm | AE8: AI flags hot day | AF8: AI outcome | AG8: Reference station hot | AH8: Representation gap | AI8: Recommended control action | AK8: First trigger dates | AN8: T_Day line | AO8: Capacity line | AP8: CUSUM h line
A9: 1 | B9: =2+(SelYear-1979)*153+A9-1 -> 6581 | C9: =INDEX(Data_Heathrow!$A:$A,B9) -> 44682 | D9: =INDEX(Data_Heathrow!$E:$E,B9) -> 17.1 | E9: =INDEX(Data_Heathrow!$Q:$Q,B9) -> 0 | F9: =INDEX(Data_Heathrow!$T:$T,B9) | G9: =IF(AND(Drift_Rate<>0,A9>=Drift_Start),Drift_Rate*(A9-Drift_Start+1)/30,0) -> 0 | H9: =IF(AND(E9=1,QA_Policy="Exclude suspect"),"",IF(AND(E9=1,QA_Policy="Impute with model",ISNUMBER(F9)),F9,D9)+G9) -> 17.1 | I9: =IF(H9="","",H9+Climate_Shift+UHI_Day_Eff) -> 19.1 | J9: =INDEX(Data_Heathrow!$G:$G,B9) -> 10.4 | K9: =J9+Climate_Shift+UHI_Night_Eff -> 14.4 | L9: =IF(INDEX(Data_Heathrow!$I:$I,B9)="","",INDEX(Data_Heathrow!$I:$I,B9)) -> 12.5 | M9: =IF(L9="","",L9+Climate_Shift+(UHI_Day_Eff+UHI_Night_Eff)/2) -> 15.5 | N9: =IF(I9="",0,IF(I9>=T_Day,1,0)) -> 0 | O9: =IF(K9>=T_Night,1,0) -> 0 | P9: =IF(N9=1,1,0) -> 0 | Q9: =IF(P9>=HW_Days,1,0) -> 0 | R9: =IF(AND(N9=1,I9>=T_Red,O9=1),"RED",IF(AND(Q9=1,O9=1),"AMBER",IF(OR(N9=1,O9=1),"YELLOW","GREEN"))) -> GREEN | S9: =IF(R9="RED",3,IF(R9="AMBER",2,IF(R9="YELLOW",1,0))) -> 0 | T9: =MAX(0,0*(1-Decay)+IF(I9="",0,MAX(0,I9-T_Comfort))-Recovery_Rate*MAX(0,T_Night-K9)) -> 0 | U9: =IF(T9>Capacity,1,0) -> 0 | V9: =1/(1+EXP(-Logistic_k*(T9-Capacity))) -> 0.0024726232 | W9: =IF(M9="",0,Beta*Pop_Share_Sel*(1-Sens_Red)*MAX(0,M9-T_Mort)) -> 0 | X9: =IF(ISNUMBER(F9),F9+Coef_B1*(Climate_Shift+0),"") | Y9: =IF(AND(ISNUMBER(X9),H9<>""),H9+Climate_Shift-X9,"") | Z9: =IF(ISNUMBER(Y9),ABS(Y9),"") | AA9: =IF(COUNT(Z9:Z9)=0,"",AVERAGE(Z9:Z9)) | AB9: =IF(FALSE(),0,MAX(0,0+IF(ISNUMBER(Y9),Y9-CUSUM_k,0))) -> 0 | AC9: =IF(FALSE(),0,MAX(0,0+IF(ISNUMBER(Y9),-Y9-CUSUM_k,0))) -> 0 | AD9: =IF(OR(AB9>CUSUM_h,AC9>CUSUM_h,AND(ISNUMBER(AA9),AA9>MAE_Tol)),1,0) -> 0 | AE9: =IF(ISNUMBER(X9),IF(X9+Local_Sensing*UHI_Day_Eff>=T_Day,1,0),0) -> 0 | AF9: =IF(NOT(ISNUMBER(X9)),"n/a",IF(AND(AE9=1,N9=1),"Hit",IF(AND(AE9=0,N9=1),"Miss",IF(AND(AE9=1,N9=0),"False alarm","Correct quiet")))) -> n/a | AG9: =IF(H9="",0,IF(H9+Climate_Shift>=T_Day,1,0)) -> 0 | AH9: =IF(AND(N9=1,AG9=0),1,0) -> 0 | AI9: =IF(U9=1,"ESCALATE: surge health & transport capacity",IF(AD9=1,"Model drift: retrain, recalibrate, raise change request",IF(S9>=2,"Activate heat plan: outreach and cooling centres",IF(AND(E9=1,OR(N9=1,O9=1)),"Data QA: verify sensor before acting",IF(AF9="Miss","Review missed alert: threshold or model",IF(AH9=1,"Equity: local alert not seen at reference station","Monitor")))))) -> Monitor | AK9: First hot day | AL9: =IFERROR(INDEX($C$9:$C$161,MATCH(1,N9:N161,0)),"—") -> 44697 | AN9: =T_Day -> 28 | AO9: =Capacity -> 40 | AP9: =CUSUM_h -> 15
A10: 2 | B10: =2+(SelYear-1979)*153+A10-1 -> 6582 | C10: =INDEX(Data_Heathrow!$A:$A,B10) -> 44683 | D10: =INDEX(Data_Heathrow!$E:$E,B10) -> 16.1 | E10: =INDEX(Data_Heathrow!$Q:$Q,B10) -> 0 | F10: =INDEX(Data_Heathrow!$T:$T,B10) -> 18.201626 | G10: =IF(AND(Drift_Rate<>0,A10>=Drift_Start),Drift_Rate*(A10-Drift_Start+1)/30,0) -> 0 | H10: =IF(AND(E10=1,QA_Policy="Exclude suspect"),"",IF(AND(E10=1,QA_Policy="Impute with model",ISNUMBER(F10)),F10,D10)+G10) -> 16.1 | I10: =IF(H10="","",H10+Climate_Shift+UHI_Day_Eff) -> 18.1 | J10: =INDEX(Data_Heathrow!$G:$G,B10) -> 9 | K10: =J10+Climate_Shift+UHI_Night_Eff -> 13 | L10: =IF(INDEX(Data_Heathrow!$I:$I,B10)="","",INDEX(Data_Heathrow!$I:$I,B10)) -> 13.1 | M10: =IF(L10="","",L10+Climate_Shift+(UHI_Day_Eff+UHI_Night_Eff)/2) -> 16.1 | N10: =IF(I10="",0,IF(I10>=T_Day,1,0)) -> 0 | O10: =IF(K10>=T_Night,1,0) -> 0 | P10: =IF(N10=1,P9+1,0) -> 0 | Q10: =IF(P10>=HW_Days,1,0) -> 0 | R10: =IF(AND(N10=1,I10>=T_Red,O10=1),"RED",IF(AND(Q10=1,O10=1),"AMBER",IF(OR(N10=1,O10=1),"YELLOW","GREEN"))) -> GREEN | S10: =IF(R10="RED",3,IF(R10="AMBER",2,IF(R10="YELLOW",1,0))) -> 0 | T10: =MAX(0,T9*(1-Decay)+IF(I10="",0,MAX(0,I10-T_Comfort))-Recovery_Rate*MAX(0,T_Night-K10)) -> 0 | U10: =IF(T10>Capacity,1,0) -> 0 | V10: =1/(1+EXP(-Logistic_k*(T10-Capacity))) -> 0.0024726232 | W10: =IF(M10="",0,Beta*Pop_Share_Sel*(1-Sens_Red)*MAX(0,M10-T_Mort)) -> 0 | X10: =IF(ISNUMBER(F10),F10+Coef_B1*(Climate_Shift+G9),"") -> 18.201626 | Y10: =IF(AND(ISNUMBER(X10),H10<>""),H10+Climate_Shift-X10,"") -> -2.1016258 | Z10: =IF(ISNUMBER(Y10),ABS(Y10),"") -> 2.1016258 | AA10: =IF(COUNT(Z9:Z10)=0,"",AVERAGE(Z9:Z10)) -> 2.1016258 | AB10: =IF(AD9=1,0,MAX(0,AB9+IF(ISNUMBER(Y10),Y10-CUSUM_k,0))) -> 0 | AC10: =IF(AD9=1,0,MAX(0,AC9+IF(ISNUMBER(Y10),-Y10-CUSUM_k,0))) -> 1.1016258 | AD10: =IF(OR(AB10>CUSUM_h,AC10>CUSUM_h,AND(ISNUMBER(AA10),AA10>MAE_Tol)),1,0) -> 0 | AE10: =IF(ISNUMBER(X10),IF(X10+Local_Sensing*UHI_Day_Eff>=T_Day,1,0),0) -> 0 | AF10: =IF(NOT(ISNUMBER(X10)),"n/a",IF(AND(AE10=1,N10=1),"Hit",IF(AND(AE10=0,N10=1),"Miss",IF(AND(AE10=1,N10=0),"False alarm","Correct quiet")))) -> Correct quiet | AG10: =IF(H10="",0,IF(H10+Climate_Shift>=T_Day,1,0)) -> 0 | AH10: =IF(AND(N10=1,AG10=0),1,0) -> 0 | AI10: =IF(U10=1,"ESCALATE: surge health & transport capacity",IF(AD10=1,"Model drift: retrain, recalibrate, raise change request",IF(S10>=2,"Activate heat plan: outreach and cooling centres",IF(AND(E10=1,OR(N10=1,O10=1)),"Data QA: verify sensor before acting",IF(AF10="Miss","Review missed alert: threshold or model",IF(AH10=1,"Equity: local alert not seen at reference station","Monitor")))))) -> Monitor | AK10: First heatwave day | AL10: =IFERROR(INDEX($C$9:$C$161,MATCH(1,Q9:Q161,0)),"—") -> 44728 | AN10: =T_Day -> 28 | AO10: =Capacity -> 40 | AP10: =CUSUM_h -> 15
A11: 3 | B11: =2+(SelYear-1979)*153+A11-1 -> 6583 | C11: =INDEX(Data_Heathrow!$A:$A,B11) -> 44684 | D11: =INDEX(Data_Heathrow!$E:$E,B11) -> 20 | E11: =INDEX(Data_Heathrow!$Q:$Q,B11) -> 0 | F11: =INDEX(Data_Heathrow!$T:$T,B11) -> 17.310136 | G11: =IF(AND(Drift_Rate<>0,A11>=Drift_Start),Drift_Rate*(A11-Drift_Start+1)/30,0) -> 0 | H11: =IF(AND(E11=1,QA_Policy="Exclude suspect"),"",IF(AND(E11=1,QA_Policy="Impute with model",ISNUMBER(F11)),F11,D11)+G11) -> 20 | I11: =IF(H11="","",H11+Climate_Shift+UHI_Day_Eff) -> 22 | J11: =INDEX(Data_Heathrow!$G:$G,B11) -> 10.6 | K11: =J11+Climate_Shift+UHI_Night_Eff -> 14.6 | L11: =IF(INDEX(Data_Heathrow!$I:$I,B11)="","",INDEX(Data_Heathrow!$I:$I,B11)) -> 13.3 | M11: =IF(L11="","",L11+Climate_Shift+(UHI_Day_Eff+UHI_Night_Eff)/2) -> 16.3 | N11: =IF(I11="",0,IF(I11>=T_Day,1,0)) -> 0 | O11: =IF(K11>=T_Night,1,0) -> 0 | P11: =IF(N11=1,P10+1,0) -> 0 | Q11: =IF(P11>=HW_Days,1,0) -> 0 | R11: =IF(AND(N11=1,I11>=T_Red,O11=1),"RED",IF(AND(Q11=1,O11=1),"AMBER",IF(OR(N11=1,O11=1),"YELLOW","GREEN"))) -> GREEN | S11: =IF(R11="RED",3,IF(R11="AMBER",2,IF(R11="YELLOW",1,0))) -> 0 | T11: =MAX(0,T10*(1-Decay)+IF(I11="",0,MAX(0,I11-T_Comfort))-Recovery_Rate*MAX(0,T_Night-K11)) -> 0 | U11: =IF(T11>Capacity,1,0) -> 0 | V11: =1/(1+EXP(-Logistic_k*(T11-Capacity))) -> 0.0024726232 | W11: =IF(M11="",0,Beta*Pop_Share_Sel*(1-Sens_Red)*MAX(0,M11-T_Mort)) -> 0 | X11: =IF(ISNUMBER(F11),F11+Coef_B1*(Climate_Shift+G10),"") -> 17.310136 | Y11: =IF(AND(ISNUMBER(X11),H11<>""),H11+Climate_Shift-X11,"") -> 2.6898642 | Z11: =IF(ISNUMBER(Y11),ABS(Y11),"") -> 2.6898642 | AA11: =IF(COUNT(Z9:Z11)=0,"",AVERAGE(Z9:Z11)) -> 2.395745 | AB11: =IF(AD10=1,0,MAX(0,AB10+IF(ISNUMBER(Y11),Y11-CUSUM_k,0))) -> 1.6898642 | AC11: =IF(AD10=1,0,MAX(0,AC10+IF(ISNUMBER(Y11),-Y11-CUSUM_k,0))) -> 0 | AD11: =IF(OR(AB11>CUSUM_h,AC11>CUSUM_h,AND(ISNUMBER(AA11),AA11>MAE_Tol)),1,0) -> 0 | AE11: =IF(ISNUMBER(X11),IF(X11+Local_Sensing*UHI_Day_Eff>=T_Day,1,0),0) -> 0 | AF11: =IF(NOT(ISNUMBER(X11)),"n/a",IF(AND(AE11=1,N11=1),"Hit",IF(AND(AE11=0,N11=1),"Miss",IF(AND(AE11=1,N11=0),"False alarm","Correct quiet")))) -> Correct quiet | AG11: =IF(H11="",0,IF(H11+Climate_Shift>=T_Day,1,0)) -> 0 | AH11: =IF(AND(N11=1,AG11=0),1,0) -> 0 | AI11: =IF(U11=1,"ESCALATE: surge health & transport capacity",IF(AD11=1,"Model drift: retrain, recalibrate, raise change request",IF(S11>=2,"Activate heat plan: outreach and cooling centres",IF(AND(E11=1,OR(N11=1,O11=1)),"Data QA: verify sensor before acting",IF(AF11="Miss","Review missed alert: threshold or model",IF(AH11=1,"Equity: local alert not seen at reference station","Monitor")))))) -> Monitor | AK11: First tipping day | AL11: =IFERROR(INDEX($C$9:$C$161,MATCH(1,U9:U161,0)),"—") -> 44760 | AN11: =T_Day -> 28 | AO11: =Capacity -> 40 | AP11: =CUSUM_h -> 15
A12: 4 | B12: =2+(SelYear-1979)*153+A12-1 -> 6584 | C12: =INDEX(Data_Heathrow!$A:$A,B12) -> 44685 | D12: =INDEX(Data_Heathrow!$E:$E,B12) -> 19.9 | E12: =INDEX(Data_Heathrow!$Q:$Q,B12) -> 0 | F12: =INDEX(Data_Heathrow!$T:$T,B12) -> 20.505559 | G12: =IF(AND(Drift_Rate<>0,A12>=Drift_Start),Drift_Rate*(A12-Drift_Start+1)/30,0) -> 0 | H12: =IF(AND(E12=1,QA_Policy="Exclude suspect"),"",IF(AND(E12=1,QA_Policy="Impute with model",ISNUMBER(F12)),F12,D12)+G12) -> 19.9 | I12: =IF(H12="","",H12+Climate_Shift+UHI_Day_Eff) -> 21.9 | J12: =INDEX(Data_Heathrow!$G:$G,B12) -> 10.5 | K12: =J12+Climate_Shift+UHI_Night_Eff -> 14.5 | L12: =IF(INDEX(Data_Heathrow!$I:$I,B12)="","",INDEX(Data_Heathrow!$I:$I,B12)) -> 15.2 | M12: =IF(L12="","",L12+Climate_Shift+(UHI_Day_Eff+UHI_Night_Eff)/2) -> 18.2 | N12: =IF(I12="",0,IF(I12>=T_Day,1,0)) -> 0 | O12: =IF(K12>=T_Night,1,0) -> 0 | P12: =IF(N12=1,P11+1,0) -> 0 | Q12: =IF(P12>=HW_Days,1,0) -> 0 | R12: =IF(AND(N12=1,I12>=T_Red,O12=1),"RED",IF(AND(Q12=1,O12=1),"AMBER",IF(OR(N12=1,O12=1),"YELLOW","GREEN"))) -> GREEN | S12: =IF(R12="RED",3,IF(R12="AMBER",2,IF(R12="YELLOW",1,0))) -> 0 | T12: =MAX(0,T11*(1-Decay)+IF(I12="",0,MAX(0,I12-T_Comfort))-Recovery_Rate*MAX(0,T_Night-K12)) -> 0 | U12: =IF(T12>Capacity,1,0) -> 0 | V12: =1/(1+EXP(-Logistic_k*(T12-Capacity))) -> 0.0024726232 | W12: =IF(M12="",0,Beta*Pop_Share_Sel*(1-Sens_Red)*MAX(0,M12-T_Mort)) -> 0 | X12: =IF(ISNUMBER(F12),F12+Coef_B1*(Climate_Shift+G11),"") -> 20.505559 | Y12: =IF(AND(ISNUMBER(X12),H12<>""),H12+Climate_Shift-X12,"") -> -0.60555869 | Z12: =IF(ISNUMBER(Y12),ABS(Y12),"") -> 0.60555869 | AA12: =IF(COUNT(Z9:Z12)=0,"",AVERAGE(Z9:Z12)) -> 1.7990162 | AB12: =IF(AD11=1,0,MAX(0,AB11+IF(ISNUMBER(Y12),Y12-CUSUM_k,0))) -> 0.084305466 | AC12: =IF(AD11=1,0,MAX(0,AC11+IF(ISNUMBER(Y12),-Y12-CUSUM_k,0))) -> 0 | AD12: =IF(OR(AB12>CUSUM_h,AC12>CUSUM_h,AND(ISNUMBER(AA12),AA12>MAE_Tol)),1,0) -> 0 | AE12: =IF(ISNUMBER(X12),IF(X12+Local_Sensing*UHI_Day_Eff>=T_Day,1,0),0) -> 0 | AF12: =IF(NOT(ISNUMBER(X12)),"n/a",IF(AND(AE12=1,N12=1),"Hit",IF(AND(AE12=0,N12=1),"Miss",IF(AND(AE12=1,N12=0),"False alarm","Correct quiet")))) -> Correct quiet | AG12: =IF(H12="",0,IF(H12+Climate_Shift>=T_Day,1,0)) -> 0 | AH12: =IF(AND(N12=1,AG12=0),1,0) -> 0 | AI12: =IF(U12=1,"ESCALATE: surge health & transport capacity",IF(AD12=1,"Model drift: retrain, recalibrate, raise change request",IF(S12>=2,"Activate heat plan: outreach and cooling centres",IF(AND(E12=1,OR(N12=1,O12=1)),"Data QA: verify sensor before acting",IF(AF12="Miss","Review missed alert: threshold or model",IF(AH12=1,"Equity: local alert not seen at reference station","Monitor")))))) -> Monitor | AK12: First drift alarm | AL12: =IFERROR(INDEX($C$9:$C$161,MATCH(1,AD9:AD161,0)),"—") -> 44760 | AN12: =T_Day -> 28 | AO12: =Capacity -> 40 | AP12: =CUSUM_h -> 15
A13: 5 | B13: =2+(SelYear-1979)*153+A13-1 -> 6585 | C13: =INDEX(Data_Heathrow!$A:$A,B13) -> 44686 | D13: =INDEX(Data_Heathrow!$E:$E,B13) -> 23.3 | E13: =INDEX(Data_Heathrow!$Q:$Q,B13) -> 0 | F13: =INDEX(Data_Heathrow!$T:$T,B13) -> 20.367159 | G13: =IF(AND(Drift_Rate<>0,A13>=Drift_Start),Drift_Rate*(A13-Drift_Start+1)/30,0) -> 0 | H13: =IF(AND(E13=1,QA_Policy="Exclude suspect"),"",IF(AND(E13=1,QA_Policy="Impute with model",ISNUMBER(F13)),F13,D13)+G13) -> 23.3 | I13: =IF(H13="","",H13+Climate_Shift+UHI_Day_Eff) -> 25.3 | J13: =INDEX(Data_Heathrow!$G:$G,B13) -> 7.5 | K13: =J13+Climate_Shift+UHI_Night_Eff -> 11.5 | L13: =IF(INDEX(Data_Heathrow!$I:$I,B13)="","",INDEX(Data_Heathrow!$I:$I,B13)) -> 13.7 | M13: =IF(L13="","",L13+Climate_Shift+(UHI_Day_Eff+UHI_Night_Eff)/2) -> 16.7 | N13: =IF(I13="",0,IF(I13>=T_Day,1,0)) -> 0 | O13: =IF(K13>=T_Night,1,0) -> 0 | P13: =IF(N13=1,P12+1,0) -> 0 | Q13: =IF(P13>=HW_Days,1,0) -> 0 | R13: =IF(AND(N13=1,I13>=T_Red,O13=1),"RED",IF(AND(Q13=1,O13=1),"AMBER",IF(OR(N13=1,O13=1),"YELLOW","GREEN"))) -> GREEN | S13: =IF(R13="RED",3,IF(R13="AMBER",2,IF(R13="YELLOW",1,0))) -> 0 | T13: =MAX(0,T12*(1-Decay)+IF(I13="",0,MAX(0,I13-T_Comfort))-Recovery_Rate*MAX(0,T_Night-K13)) -> 0 | U13: =IF(T13>Capacity,1,0) -> 0 | V13: =1/(1+EXP(-Logistic_k*(T13-Capacity))) -> 0.0024726232 | W13: =IF(M13="",0,Beta*Pop_Share_Sel*(1-Sens_Red)*MAX(0,M13-T_Mort)) -> 0 | X13: =IF(ISNUMBER(F13),F13+Coef_B1*(Climate_Shift+G12),"") -> 20.367159 | Y13: =IF(AND(ISNUMBER(X13),H13<>""),H13+Climate_Shift-X13,"") -> 2.932841 | Z13: =IF(ISNUMBER(Y13),ABS(Y13),"") -> 2.932841 | AA13: =IF(COUNT(Z9:Z13)=0,"",AVERAGE(Z9:Z13)) -> 2.0824724 | AB13: =IF(AD12=1,0,MAX(0,AB12+IF(ISNUMBER(Y13),Y13-CUSUM_k,0))) -> 2.0171465 | AC13: =IF(AD12=1,0,MAX(0,AC12+IF(ISNUMBER(Y13),-Y13-CUSUM_k,0))) -> 0 | AD13: =IF(OR(AB13>CUSUM_h,AC13>CUSUM_h,AND(ISNUMBER(AA13),AA13>MAE_Tol)),1,0) -> 0 | AE13: =IF(ISNUMBER(X13),IF(X13+Local_Sensing*UHI_Day_Eff>=T_Day,1,0),0) -> 0 | AF13: =IF(NOT(ISNUMBER(X13)),"n/a",IF(AND(AE13=1,N13=1),"Hit",IF(AND(AE13=0,N13=1),"Miss",IF(AND(AE13=1,N13=0),"False alarm","Correct quiet")))) -> Correct quiet | AG13: =IF(H13="",0,IF(H13+Climate_Shift>=T_Day,1,0)) -> 0 | AH13: =IF(AND(N13=1,AG13=0),1,0) -> 0 | AI13: =IF(U13=1,"ESCALATE: surge health & transport capacity",IF(AD13=1,"Model drift: retrain, recalibrate, raise change request",IF(S13>=2,"Activate heat plan: outreach and cooling centres",IF(AND(E13=1,OR(N13=1,O13=1)),"Data QA: verify sensor before acting",IF(AF13="Miss","Review missed alert: threshold or model",IF(AH13=1,"Equity: local alert not seen at reference station","Monitor")))))) -> Monitor | AK13: First representation gap | AL13: =IFERROR(INDEX($C$9:$C$161,MATCH(1,AH9:AH161,0)),"—") -> 44697 | AN13: =T_Day -> 28 | AO13: =Capacity -> 40 | AP13: =CUSUM_h -> 15
A14: 6 | B14: =2+(SelYear-1979)*153+A14-1 -> 6586 | C14: =INDEX(Data_Heathrow!$A:$A,B14) -> 44687 | D14: =INDEX(Data_Heathrow!$E:$E,B14) -> 20.3 | E14: =INDEX(Data_Heathrow!$Q:$Q,B14) -> 0 | F14: =INDEX(Data_Heathrow!$T:$T,B14) -> 23.294077 | G14: =IF(AND(Drift_Rate<>0,A14>=Drift_Start),Drift_Rate*(A14-Drift_Start+1)/30,0) -> 0 | H14: =IF(AND(E14=1,QA_Policy="Exclude suspect"),"",IF(AND(E14=1,QA_Policy="Impute with model",ISNUMBER(F14)),F14,D14)+G14) -> 20.3 | I14: =IF(H14="","",H14+Climate_Shift+UHI_Day_Eff) -> 22.3 | J14: =INDEX(Data_Heathrow!$G:$G,B14) -> 9.2 | K14: =J14+Climate_Shift+UHI_Night_Eff -> 13.2 | L14: =IF(INDEX(Data_Heathrow!$I:$I,B14)="","",INDEX(Data_Heathrow!$I:$I,B14)) -> 16.2 | M14: =IF(L14="","",L14+Climate_Shift+(UHI_Day_Eff+UHI_Night_Eff)/2) -> 19.2 | N14: =IF(I14="",0,IF(I14>=T_Day,1,0)) -> 0 | O14: =IF(K14>=T_Night,1,0) -> 0 | P14: =IF(N14=1,P13+1,0) -> 0 | Q14: =IF(P14>=HW_Days,1,0) -> 0 | R14: =IF(AND(N14=1,I14>=T_Red,O14=1),"RED",IF(AND(Q14=1,O14=1),"AMBER",IF(OR(N14=1,O14=1),"YELLOW","GREEN"))) -> GREEN | S14: =IF(R14="RED",3,IF(R14="AMBER",2,IF(R14="YELLOW",1,0))) -> 0 | T14: =MAX(0,T13*(1-Decay)+IF(I14="",0,MAX(0,I14-T_Comfort))-Recovery_Rate*MAX(0,T_Night-K14)) -> 0 | U14: =IF(T14>Capacity,1,0) -> 0 | V14: =1/(1+EXP(-Logistic_k*(T14-Capacity))) -> 0.0024726232 | W14: =IF(M14="",0,Beta*Pop_Share_Sel*(1-Sens_Red)*MAX(0,M14-T_Mort)) -> 0 | X14: =IF(ISNUMBER(F14),F14+Coef_B1*(Climate_Shift+G13),"") -> 23.294077 | Y14: =IF(AND(ISNUMBER(X14),H14<>""),H14+Climate_Shift-X14,"") -> -2.9940767 | Z14: =IF(ISNUMBER(Y14),ABS(Y14),"") -> 2.9940767 | AA14: =IF(COUNT(Z9:Z14)=0,"",AVERAGE(Z9:Z14)) -> 2.2647933 | AB14: =IF(AD13=1,0,MAX(0,AB13+IF(ISNUMBER(Y14),Y14-CUSUM_k,0))) -> 0 | AC14: =IF(AD13=1,0,MAX(0,AC13+IF(ISNUMBER(Y14),-Y14-CUSUM_k,0))) -> 1.9940767 | AD14: =IF(OR(AB14>CUSUM_h,AC14>CUSUM_h,AND(ISNUMBER(AA14),AA14>MAE_Tol)),1,0) -> 0 | AE14: =IF(ISNUMBER(X14),IF(X14+Local_Sensing*UHI_Day_Eff>=T_Day,1,0),0) -> 0 | AF14: =IF(NOT(ISNUMBER(X14)),"n/a",IF(AND(AE14=1,N14=1),"Hit",IF(AND(AE14=0,N14=1),"Miss",IF(AND(AE14=1,N14=0),"False alarm","Correct quiet")))) -> Correct quiet | AG14: =IF(H14="",0,IF(H14+Climate_Shift>=T_Day,1,0)) -> 0 | AH14: =IF(AND(N14=1,AG14=0),1,0) -> 0 | AI14: =IF(U14=1,"ESCALATE: surge health & transport capacity",IF(AD14=1,"Model drift: retrain, recalibrate, raise change request",IF(S14>=2,"Activate heat plan: outreach and cooling centres",IF(AND(E14=1,OR(N14=1,O14=1)),"Data QA: verify sensor before acting",IF(AF14="Miss","Review missed alert: threshold or model",IF(AH14=1,"Equity: local alert not seen at reference station","Monitor")))))) -> Monitor | AN14: =T_Day -> 28 | AO14: =Capacity -> 40 | AP14: =CUSUM_h -> 15
A15: 7 | B15: =2+(SelYear-1979)*153+A15-1 -> 6587 | C15: =INDEX(Data_Heathrow!$A:$A,B15) -> 44688 | D15: =INDEX(Data_Heathrow!$E:$E,B15) -> 20.6 | E15: =INDEX(Data_Heathrow!$Q:$Q,B15) -> 0 | F15: =INDEX(Data_Heathrow!$T:$T,B15) -> 20.87684 | G15: =IF(AND(Drift_Rate<>0,A15>=Drift_Start),Drift_Rate*(A15-Drift_Start+1)/30,0) -> 0 | H15: =IF(AND(E15=1,QA_Policy="Exclude suspect"),"",IF(AND(E15=1,QA_Policy="Impute with model",ISNUMBER(F15)),F15,D15)+G15) -> 20.6 | I15: =IF(H15="","",H15+Climate_Shift+UHI_Day_Eff) -> 22.6 | J15: =INDEX(Data_Heathrow!$G:$G,B15) -> 12.4 | K15: =J15+Climate_Shift+UHI_Night_Eff -> 16.4 | L15: =IF(INDEX(Data_Heathrow!$I:$I,B15)="","",INDEX(Data_Heathrow!$I:$I,B15)) -> 16.4 | M15: =IF(L15="","",L15+Climate_Shift+(UHI_Day_Eff+UHI_Night_Eff)/2) -> 19.4 | N15: =IF(I15="",0,IF(I15>=T_Day,1,0)) -> 0 | O15: =IF(K15>=T_Night,1,0) -> 0 | P15: =IF(N15=1,P14+1,0) -> 0 | Q15: =IF(P15>=HW_Days,1,0) -> 0 | R15: =IF(AND(N15=1,I15>=T_Red,O15=1),"RED",IF(AND(Q15=1,O15=1),"AMBER",IF(OR(N15=1,O15=1),"YELLOW","GREEN"))) -> GREEN | S15: =IF(R15="RED",3,IF(R15="AMBER",2,IF(R15="YELLOW",1,0))) -> 0 | T15: =MAX(0,T14*(1-Decay)+IF(I15="",0,MAX(0,I15-T_Comfort))-Recovery_Rate*MAX(0,T_Night-K15)) -> 0 | U15: =IF(T15>Capacity,1,0) -> 0 | V15: =1/(1+EXP(-Logistic_k*(T15-Capacity))) -> 0.0024726232 | W15: =IF(M15="",0,Beta*Pop_Share_Sel*(1-Sens_Red)*MAX(0,M15-T_Mort)) -> 0 | X15: =IF(ISNUMBER(F15),F15+Coef_B1*(Climate_Shift+G14),"") -> 20.87684 | Y15: =IF(AND(ISNUMBER(X15),H15<>""),H15+Climate_Shift-X15,"") -> -0.27684003 | Z15: =IF(ISNUMBER(Y15),ABS(Y15),"") -> 0.27684003 | AA15: =IF(COUNT(Z9:Z15)=0,"",AVERAGE(Z9:Z15)) -> 1.9334677 | AB15: =IF(AD14=1,0,MAX(0,AB14+IF(ISNUMBER(Y15),Y15-CUSUM_k,0))) -> 0 | AC15: =IF(AD14=1,0,MAX(0,AC14+IF(ISNUMBER(Y15),-Y15-CUSUM_k,0))) -> 1.2709168 | AD15: =IF(OR(AB15>CUSUM_h,AC15>CUSUM_h,AND(ISNUMBER(AA15),AA15>MAE_Tol)),1,0) -> 0 | AE15: =IF(ISNUMBER(X15),IF(X15+Local_Sensing*UHI_Day_Eff>=T_Day,1,0),0) -> 0 | AF15: =IF(NOT(ISNUMBER(X15)),"n/a",IF(AND(AE15=1,N15=1),"Hit",IF(AND(AE15=0,N15=1),"Miss",IF(AND(AE15=1,N15=0),"False alarm","Correct quiet")))) -> Correct quiet | AG15: =IF(H15="",0,IF(H15+Climate_Shift>=T_Day,1,0)) -> 0 | AH15: =IF(AND(N15=1,AG15=0),1,0) -> 0 | AI15: =IF(U15=1,"ESCALATE: surge health & transport capacity",IF(AD15=1,"Model drift: retrain, recalibrate, raise change request",IF(S15>=2,"Activate heat plan: outreach and cooling centres",IF(AND(E15=1,OR(N15=1,O15=1)),"Data QA: verify sensor before acting",IF(AF15="Miss","Review missed alert: threshold or model",IF(AH15=1,"Equity: local alert not seen at reference station","Monitor")))))) -> Monitor | AN15: =T_Day -> 28 | AO15: =Capacity -> 40 | AP15: =CUSUM_h -> 15
